<?xml version="1.0"?>
<robot name="flywheel_robot">
    <link name="flywheel">
        <visual>
            <origin xyz="0 0 0" rpy="0 0 0"/>
            <geometry>
            <mesh filename="package://home/simulations/cad/STL/reaction_wheel.STL" scale="0.001 0.001 0.001"/>
            </geometry>
            <material name="Gray">
            <color rgba="0.5 0.5 0.5 1.0"/>
            </material>
        </visual>
        <inertial>
            <origin rpy="-3.141593 3.141593 -3.141593" xyz="0.000000 0.000000 0.000000" />
            <inertia ixy="0.0" ixx="0.24166665971279" ixz="0.0" izz="0.04166666790843" iyz="0.0" iyy="0.21666666865349" />
            <mass value="10.0" />
        </inertial>
    </link>

    <link name="pendulum">
        <visual>
            <origin xyz="0 0 0" rpy="0 0 0"/>
            <geometry>
            <mesh filename="package://home/simulations/cad/STL/pendulum_arm.STL" scale="0.001 0.001 0.001"/>
            </geometry>
            <material name="Gray">
            <color rgba="0.5 0.5 0.5 1.0"/>
            </material>
        </visual>
        <inertial>
            <origin rpy="-3.141593 3.141593 -3.141593" xyz="0.000000 0.000000 0.000000" />
            <inertia ixy="0.0" ixx="0.24166665971279" ixz="0.0" izz="0.04166666790843" iyz="0.0" iyy="0.21666666865349" />
            <mass value="10.0" />
        </inertial>
    </link>

    <link name="bottom_swingup">
        <visual>
            <origin xyz="0 0 0" rpy="0 0 0"/>
            <geometry>
            <mesh filename="package://home/simulations/cad/STL/bottom_swingup.STL" scale="0.001 0.001 0.001"/>
            </geometry>
            <material name="Gray">
            <color rgba="0.5 0.5 0.5 1.0"/>
            </material>
        </visual>
        <inertial>
            <origin rpy="-3.141593 3.141593 -3.141593" xyz="0.000000 0.000000 0.000000" />
            <inertia ixy="0.0" ixx="0.24166665971279" ixz="0.0" izz="0.04166666790843" iyz="0.0" iyy="0.21666666865349" />
            <mass value="10.0" />
        </inertial>
    </link>

    <joint name="actuated_joint" type="continuous">
        <axis xyz="0 0 1" />
        <parent link="flywheel" />
        <child link="pendulum" />
        <origin rpy="-1.570770 3.141593 -3.141593" xyz="0.000000 -0.180000 -0.250000" />
    </joint>

    <joint name="unactuated_joint" type="continuous">
        <axis xyz="0 0 1" />
        <parent link="pendulum" />
        <child link="bottom_swingup" />
        <origin rpy="-1.570771 3.141593 3.141593" xyz="0.000000 0.180000 -0.250000" />
    </joint>
</robot>
